 
Traceback (most recent call last):
  File "/home/s60030037/tempSensorRTC/temp_rtc/tempSensorRTC.py", line 9, in <module>
    rtcI2C=busio.I2C(SCL,SDA)
  File "/usr/local/lib/python3.7/dist-packages/busio.py", line 31, in __init__
    self.init(scl, sda, frequency)
  File "/usr/local/lib/python3.7/dist-packages/busio.py", line 65, in init
    self._i2c = _I2C(portId, mode=_I2C.MASTER, baudrate=frequency)
  File "/usr/local/lib/python3.7/dist-packages/adafruit_blinka/microcontroller/generic_linux/i2c.py", line 24, in __init__
    self._i2c_bus = smbus.SMBus(bus_num)
  File "/usr/local/lib/python3.7/dist-packages/Adafruit_PureIO/smbus.py", line 125, in __init__
    self.open(bus)
  File "/usr/local/lib/python3.7/dist-packages/Adafruit_PureIO/smbus.py", line 150, in open
    self._device = open("/dev/i2c-{0}".format(bus), "r+b", buffering=0)
PermissionError: [Errno 13] Permission denied: '/dev/i2c-1'
sudo: no tty present and no askpass program specified
<Response [200]>
<Response [200]>
<Response [200]>
<Response [200]>
<Response [200]>
<Response [200]>
Traceback (most recent call last):
  File "/usr/lib/python3/dist-packages/urllib3/connection.py", line 159, in _new_conn
    (self._dns_host, self.port), self.timeout, **extra_kw)
  File "/usr/lib/python3/dist-packages/urllib3/util/connection.py", line 80, in create_connection
    raise err
  File "/usr/lib/python3/dist-packages/urllib3/util/connection.py", line 70, in create_connection
    sock.connect(sa)
ConnectionRefusedError: [Errno 111] Connection refused

During handling of the above exception, another exception occurred:

Traceback (most recent call last):
  File "/usr/lib/python3/dist-packages/urllib3/connectionpool.py", line 600, in urlopen
    chunked=chunked)
  File "/usr/lib/python3/dist-packages/urllib3/connectionpool.py", line 354, in _make_request
    conn.request(method, url, **httplib_request_kw)
  File "/usr/lib/python3.7/http/client.py", line 1244, in request
    self._send_request(method, url, body, headers, encode_chunked)
  File "/usr/lib/python3.7/http/client.py", line 1290, in _send_request
    self.endheaders(body, encode_chunked=encode_chunked)
  File "/usr/lib/python3.7/http/client.py", line 1239, in endheaders
    self._send_output(message_body, encode_chunked=encode_chunked)
  File "/usr/lib/python3.7/http/client.py", line 1026, in _send_output
    self.send(msg)
  File "/usr/lib/python3.7/http/client.py", line 966, in send
    self.connect()
  File "/usr/lib/python3/dist-packages/urllib3/connection.py", line 181, in connect
    conn = self._new_conn()
  File "/usr/lib/python3/dist-packages/urllib3/connection.py", line 168, in _new_conn
    self, "Failed to establish a new connection: %s" % e)
urllib3.exceptions.NewConnectionError: <urllib3.connection.HTTPConnection object at 0x75ebf050>: Failed to establish a new connection: [Errno 111] Connection refused

During handling of the above exception, another exception occurred:

Traceback (most recent call last):
  File "/usr/lib/python3/dist-packages/requests/adapters.py", line 449, in send
    timeout=timeout
  File "/usr/lib/python3/dist-packages/urllib3/connectionpool.py", line 638, in urlopen
    _stacktrace=sys.exc_info()[2])
  File "/usr/lib/python3/dist-packages/urllib3/util/retry.py", line 398, in increment
    raise MaxRetryError(_pool, url, error or ResponseError(cause))
urllib3.exceptions.MaxRetryError: HTTPConnectionPool(host='localhost', port=3009): Max retries exceeded with url: /addData (Caused by NewConnectionError('<urllib3.connection.HTTPConnection object at 0x75ebf050>: Failed to establish a new connection: [Errno 111] Connection refused'))

During handling of the above exception, another exception occurred:

Traceback (most recent call last):
  File "/home/s60030037/tempSensorRTC/temp_rtc/tempSensorRTC.py", line 26, in <module>
    res=requests.post('http://localhost:3000/addData',tempSensorRTC)
  File "/usr/lib/python3/dist-packages/requests/api.py", line 116, in post
    return request('post', url, data=data, json=json, **kwargs)
  File "/usr/lib/python3/dist-packages/requests/api.py", line 60, in request
    return session.request(method=method, url=url, **kwargs)
  File "/usr/lib/python3/dist-packages/requests/sessions.py", line 533, in request
    resp = self.send(prep, **send_kwargs)
  File "/usr/lib/python3/dist-packages/requests/sessions.py", line 646, in send
    r = adapter.send(request, **kwargs)
  File "/usr/lib/python3/dist-packages/requests/adapters.py", line 516, in send
    raise ConnectionError(e, request=request)
requests.exceptions.ConnectionError: HTTPConnectionPool(host='localhost', port=3009): Max retries exceeded with url: /addData (Caused by NewConnectionError('<urllib3.connection.HTTPConnection object at 0x75ebf050>: Failed to establish a new connection: [Errno 111] Connection refused'))
<Response [200]>
<Response [200]>
<Response [200]>
<Response [200]>
<Response [200]>
<Response [200]>
<Response [200]>
<Response [200]>
<Response [200]>
<Response [200]>
<Response [200]>
<Response [200]>
<Response [200]>
<Response [200]>
<Response [200]>
<Response [200]>
<Response [200]>
<Response [200]>
<Response [200]>
<Response [200]>
<Response [200]>
<Response [200]>
<Response [200]>
<Response [200]>
<Response [200]>
<Response [200]>
<Response [200]>
<Response [200]>
<Response [200]>
<Response [200]>
<Response [200]>
<Response [200]>
<Response [200]>
<Response [200]>
<Response [200]>
<Response [200]>
<Response [200]>
<Response [200]>
<Response [200]>
<Response [200]>
<Response [200]>
<Response [200]>
<Response [200]>
<Response [200]>
<Response [200]>
<Response [200]>
<Response [200]>
<Response [200]>
<Response [200]>
<Response [200]>
<Response [200]>
<Response [200]>
<Response [200]>
<Response [200]>
<Response [200]>
<Response [200]>
<Response [200]>
<Response [200]>
<Response [200]>
<Response [200]>
<Response [200]>
<Response [200]>
<Response [200]>
<Response [200]>
<Response [200]>
<Response [200]>
<Response [200]>
<Response [200]>
<Response [200]>
<Response [200]>
<Response [200]>
<Response [200]>
<Response [200]>
<Response [200]>
<Response [200]>
<Response [200]>
<Response [200]>
<Response [200]>
<Response [200]>
<Response [200]>
<Response [200]>
<Response [200]>
<Response [200]>
<Response [200]>
<Response [200]>
<Response [200]>
<Response [200]>
<Response [200]>
<Response [200]>
<Response [200]>
<Response [200]>
<Response [200]>
<Response [200]>
<Response [200]>
<Response [200]>
<Response [200]>
<Response [200]>
<Response [200]>
<Response [200]>
<Response [200]>
<Response [200]>
<Response [200]>
<Response [200]>
<Response [200]>
<Response [200]>
<Response [200]>
<Response [200]>
<Response [200]>
<Response [200]>
<Response [200]>
<Response [200]>
<Response [200]>
<Response [200]>
<Response [200]>
<Response [200]>
<Response [200]>
Traceback (most recent call last):
  File "/usr/local/lib/python3.7/dist-packages/adafruit_bus_device/i2c_device.py", line 172, in __probe_for_device
    self.i2c.writeto(self.device_address, b"")
  File "/usr/local/lib/python3.7/dist-packages/busio.py", line 116, in writeto
    return self._i2c.writeto(address, buffer, stop=stop)
  File "/usr/local/lib/python3.7/dist-packages/adafruit_blinka/microcontroller/generic_linux/i2c.py", line 49, in writeto
    self._i2c_bus.write_bytes(address, buffer[start:end])
  File "/usr/local/lib/python3.7/dist-packages/Adafruit_PureIO/smbus.py", line 307, in write_bytes
    self._select_device(addr)
  File "/usr/local/lib/python3.7/dist-packages/Adafruit_PureIO/smbus.py", line 163, in _select_device
    ioctl(self._device.fileno(), I2C_SLAVE, addr & 0x7F)
OSError: [Errno 16] Device or resource busy

During handling of the above exception, another exception occurred:

Traceback (most recent call last):
  File "/usr/local/lib/python3.7/dist-packages/adafruit_bus_device/i2c_device.py", line 178, in __probe_for_device
    self.i2c.readfrom_into(self.device_address, result)
  File "/usr/local/lib/python3.7/dist-packages/busio.py", line 106, in readfrom_into
    return self._i2c.readfrom_into(address, buffer, stop=stop)
  File "/usr/local/lib/python3.7/dist-packages/adafruit_blinka/microcontroller/generic_linux/i2c.py", line 56, in readfrom_into
    readin = self._i2c_bus.read_bytes(address, end - start)
  File "/usr/local/lib/python3.7/dist-packages/Adafruit_PureIO/smbus.py", line 178, in read_bytes
    self._select_device(addr)
  File "/usr/local/lib/python3.7/dist-packages/Adafruit_PureIO/smbus.py", line 163, in _select_device
    ioctl(self._device.fileno(), I2C_SLAVE, addr & 0x7F)
OSError: [Errno 16] Device or resource busy

During handling of the above exception, another exception occurred:

Traceback (most recent call last):
  File "/home/s60030037/tempSensorRTC/temp_rtc/tempSensorRTC.py", line 10, in <module>
    rtc=adafruit_ds3231.DS3231(rtcI2C)
  File "/usr/local/lib/python3.7/dist-packages/adafruit_ds3231.py", line 107, in __init__
    self.i2c_device = I2CDevice(i2c, 0x68)
  File "/usr/local/lib/python3.7/dist-packages/adafruit_bus_device/i2c_device.py", line 68, in __init__
    self.__probe_for_device()
  File "/usr/local/lib/python3.7/dist-packages/adafruit_bus_device/i2c_device.py", line 180, in __probe_for_device
    raise ValueError("No I2C device at address: %x" % self.device_address)
ValueError: No I2C device at address: 68
Traceback (most recent call last):
  File "/usr/local/lib/python3.7/dist-packages/adafruit_bus_device/i2c_device.py", line 172, in __probe_for_device
    self.i2c.writeto(self.device_address, b"")
  File "/usr/local/lib/python3.7/dist-packages/busio.py", line 116, in writeto
    return self._i2c.writeto(address, buffer, stop=stop)
  File "/usr/local/lib/python3.7/dist-packages/adafruit_blinka/microcontroller/generic_linux/i2c.py", line 49, in writeto
    self._i2c_bus.write_bytes(address, buffer[start:end])
  File "/usr/local/lib/python3.7/dist-packages/Adafruit_PureIO/smbus.py", line 307, in write_bytes
    self._select_device(addr)
  File "/usr/local/lib/python3.7/dist-packages/Adafruit_PureIO/smbus.py", line 163, in _select_device
    ioctl(self._device.fileno(), I2C_SLAVE, addr & 0x7F)
OSError: [Errno 16] Device or resource busy

During handling of the above exception, another exception occurred:

Traceback (most recent call last):
  File "/usr/local/lib/python3.7/dist-packages/adafruit_bus_device/i2c_device.py", line 178, in __probe_for_device
    self.i2c.readfrom_into(self.device_address, result)
  File "/usr/local/lib/python3.7/dist-packages/busio.py", line 106, in readfrom_into
    return self._i2c.readfrom_into(address, buffer, stop=stop)
  File "/usr/local/lib/python3.7/dist-packages/adafruit_blinka/microcontroller/generic_linux/i2c.py", line 56, in readfrom_into
    readin = self._i2c_bus.read_bytes(address, end - start)
  File "/usr/local/lib/python3.7/dist-packages/Adafruit_PureIO/smbus.py", line 178, in read_bytes
    self._select_device(addr)
  File "/usr/local/lib/python3.7/dist-packages/Adafruit_PureIO/smbus.py", line 163, in _select_device
    ioctl(self._device.fileno(), I2C_SLAVE, addr & 0x7F)
OSError: [Errno 16] Device or resource busy

During handling of the above exception, another exception occurred:

Traceback (most recent call last):
  File "/home/s60030037/tempSensorRTC/temp_rtc/tempSensorRTC.py", line 10, in <module>
    rtc=adafruit_ds3231.DS3231(rtcI2C)
  File "/usr/local/lib/python3.7/dist-packages/adafruit_ds3231.py", line 107, in __init__
    self.i2c_device = I2CDevice(i2c, 0x68)
  File "/usr/local/lib/python3.7/dist-packages/adafruit_bus_device/i2c_device.py", line 68, in __init__
    self.__probe_for_device()
  File "/usr/local/lib/python3.7/dist-packages/adafruit_bus_device/i2c_device.py", line 180, in __probe_for_device
    raise ValueError("No I2C device at address: %x" % self.device_address)
ValueError: No I2C device at address: 68
Traceback (most recent call last):
  File "/usr/local/lib/python3.7/dist-packages/adafruit_bus_device/i2c_device.py", line 172, in __probe_for_device
    self.i2c.writeto(self.device_address, b"")
  File "/usr/local/lib/python3.7/dist-packages/busio.py", line 116, in writeto
    return self._i2c.writeto(address, buffer, stop=stop)
  File "/usr/local/lib/python3.7/dist-packages/adafruit_blinka/microcontroller/generic_linux/i2c.py", line 49, in writeto
    self._i2c_bus.write_bytes(address, buffer[start:end])
  File "/usr/local/lib/python3.7/dist-packages/Adafruit_PureIO/smbus.py", line 307, in write_bytes
    self._select_device(addr)
  File "/usr/local/lib/python3.7/dist-packages/Adafruit_PureIO/smbus.py", line 163, in _select_device
    ioctl(self._device.fileno(), I2C_SLAVE, addr & 0x7F)
OSError: [Errno 16] Device or resource busy

During handling of the above exception, another exception occurred:

Traceback (most recent call last):
  File "/usr/local/lib/python3.7/dist-packages/adafruit_bus_device/i2c_device.py", line 178, in __probe_for_device
    self.i2c.readfrom_into(self.device_address, result)
  File "/usr/local/lib/python3.7/dist-packages/busio.py", line 106, in readfrom_into
    return self._i2c.readfrom_into(address, buffer, stop=stop)
  File "/usr/local/lib/python3.7/dist-packages/adafruit_blinka/microcontroller/generic_linux/i2c.py", line 56, in readfrom_into
    readin = self._i2c_bus.read_bytes(address, end - start)
  File "/usr/local/lib/python3.7/dist-packages/Adafruit_PureIO/smbus.py", line 178, in read_bytes
    self._select_device(addr)
  File "/usr/local/lib/python3.7/dist-packages/Adafruit_PureIO/smbus.py", line 163, in _select_device
    ioctl(self._device.fileno(), I2C_SLAVE, addr & 0x7F)
OSError: [Errno 16] Device or resource busy

During handling of the above exception, another exception occurred:

Traceback (most recent call last):
  File "/home/s60030037/tempSensorRTC/temp_rtc/tempSensorRTC.py", line 10, in <module>
    rtc=adafruit_ds3231.DS3231(rtcI2C)
  File "/usr/local/lib/python3.7/dist-packages/adafruit_ds3231.py", line 107, in __init__
    self.i2c_device = I2CDevice(i2c, 0x68)
  File "/usr/local/lib/python3.7/dist-packages/adafruit_bus_device/i2c_device.py", line 68, in __init__
    self.__probe_for_device()
  File "/usr/local/lib/python3.7/dist-packages/adafruit_bus_device/i2c_device.py", line 180, in __probe_for_device
    raise ValueError("No I2C device at address: %x" % self.device_address)
ValueError: No I2C device at address: 68
Traceback (most recent call last):
  File "/usr/local/lib/python3.7/dist-packages/adafruit_bus_device/i2c_device.py", line 172, in __probe_for_device
    self.i2c.writeto(self.device_address, b"")
  File "/usr/local/lib/python3.7/dist-packages/busio.py", line 116, in writeto
    return self._i2c.writeto(address, buffer, stop=stop)
  File "/usr/local/lib/python3.7/dist-packages/adafruit_blinka/microcontroller/generic_linux/i2c.py", line 49, in writeto
    self._i2c_bus.write_bytes(address, buffer[start:end])
  File "/usr/local/lib/python3.7/dist-packages/Adafruit_PureIO/smbus.py", line 307, in write_bytes
    self._select_device(addr)
  File "/usr/local/lib/python3.7/dist-packages/Adafruit_PureIO/smbus.py", line 163, in _select_device
    ioctl(self._device.fileno(), I2C_SLAVE, addr & 0x7F)
OSError: [Errno 16] Device or resource busy

During handling of the above exception, another exception occurred:

Traceback (most recent call last):
  File "/usr/local/lib/python3.7/dist-packages/adafruit_bus_device/i2c_device.py", line 178, in __probe_for_device
    self.i2c.readfrom_into(self.device_address, result)
  File "/usr/local/lib/python3.7/dist-packages/busio.py", line 106, in readfrom_into
    return self._i2c.readfrom_into(address, buffer, stop=stop)
  File "/usr/local/lib/python3.7/dist-packages/adafruit_blinka/microcontroller/generic_linux/i2c.py", line 56, in readfrom_into
    readin = self._i2c_bus.read_bytes(address, end - start)
  File "/usr/local/lib/python3.7/dist-packages/Adafruit_PureIO/smbus.py", line 178, in read_bytes
    self._select_device(addr)
  File "/usr/local/lib/python3.7/dist-packages/Adafruit_PureIO/smbus.py", line 163, in _select_device
    ioctl(self._device.fileno(), I2C_SLAVE, addr & 0x7F)
OSError: [Errno 16] Device or resource busy

During handling of the above exception, another exception occurred:

Traceback (most recent call last):
  File "/home/s60030037/tempSensorRTC/temp_rtc/tempSensorRTC.py", line 10, in <module>
    rtc=adafruit_ds3231.DS3231(rtcI2C)
  File "/usr/local/lib/python3.7/dist-packages/adafruit_ds3231.py", line 107, in __init__
    self.i2c_device = I2CDevice(i2c, 0x68)
  File "/usr/local/lib/python3.7/dist-packages/adafruit_bus_device/i2c_device.py", line 68, in __init__
    self.__probe_for_device()
  File "/usr/local/lib/python3.7/dist-packages/adafruit_bus_device/i2c_device.py", line 180, in __probe_for_device
    raise ValueError("No I2C device at address: %x" % self.device_address)
ValueError: No I2C device at address: 68
Traceback (most recent call last):
  File "/usr/local/lib/python3.7/dist-packages/adafruit_bus_device/i2c_device.py", line 172, in __probe_for_device
    self.i2c.writeto(self.device_address, b"")
  File "/usr/local/lib/python3.7/dist-packages/busio.py", line 116, in writeto
    return self._i2c.writeto(address, buffer, stop=stop)
  File "/usr/local/lib/python3.7/dist-packages/adafruit_blinka/microcontroller/generic_linux/i2c.py", line 49, in writeto
    self._i2c_bus.write_bytes(address, buffer[start:end])
  File "/usr/local/lib/python3.7/dist-packages/Adafruit_PureIO/smbus.py", line 307, in write_bytes
    self._select_device(addr)
  File "/usr/local/lib/python3.7/dist-packages/Adafruit_PureIO/smbus.py", line 163, in _select_device
    ioctl(self._device.fileno(), I2C_SLAVE, addr & 0x7F)
OSError: [Errno 16] Device or resource busy

During handling of the above exception, another exception occurred:

Traceback (most recent call last):
  File "/usr/local/lib/python3.7/dist-packages/adafruit_bus_device/i2c_device.py", line 178, in __probe_for_device
    self.i2c.readfrom_into(self.device_address, result)
  File "/usr/local/lib/python3.7/dist-packages/busio.py", line 106, in readfrom_into
    return self._i2c.readfrom_into(address, buffer, stop=stop)
  File "/usr/local/lib/python3.7/dist-packages/adafruit_blinka/microcontroller/generic_linux/i2c.py", line 56, in readfrom_into
    readin = self._i2c_bus.read_bytes(address, end - start)
  File "/usr/local/lib/python3.7/dist-packages/Adafruit_PureIO/smbus.py", line 178, in read_bytes
    self._select_device(addr)
  File "/usr/local/lib/python3.7/dist-packages/Adafruit_PureIO/smbus.py", line 163, in _select_device
    ioctl(self._device.fileno(), I2C_SLAVE, addr & 0x7F)
OSError: [Errno 16] Device or resource busy

During handling of the above exception, another exception occurred:

Traceback (most recent call last):
  File "/home/s60030037/tempSensorRTC/temp_rtc/tempSensorRTC.py", line 10, in <module>
    rtc=adafruit_ds3231.DS3231(rtcI2C)
  File "/usr/local/lib/python3.7/dist-packages/adafruit_ds3231.py", line 107, in __init__
    self.i2c_device = I2CDevice(i2c, 0x68)
  File "/usr/local/lib/python3.7/dist-packages/adafruit_bus_device/i2c_device.py", line 68, in __init__
    self.__probe_for_device()
  File "/usr/local/lib/python3.7/dist-packages/adafruit_bus_device/i2c_device.py", line 180, in __probe_for_device
    raise ValueError("No I2C device at address: %x" % self.device_address)
ValueError: No I2C device at address: 68
<Response [200]>
<Response [200]>
<Response [200]>
<Response [200]>
<Response [200]>
<Response [200]>
<Response [200]>
<Response [200]>
<Response [200]>
<Response [200]>
<Response [200]>
<Response [200]>
<Response [200]>
<Response [200]>
<Response [200]>
Traceback (most recent call last):
  File "/usr/lib/python3/dist-packages/urllib3/connection.py", line 159, in _new_conn
    (self._dns_host, self.port), self.timeout, **extra_kw)
  File "/usr/lib/python3/dist-packages/urllib3/util/connection.py", line 80, in create_connection
    raise err
  File "/usr/lib/python3/dist-packages/urllib3/util/connection.py", line 70, in create_connection
    sock.connect(sa)
ConnectionRefusedError: [Errno 111] Connection refused

During handling of the above exception, another exception occurred:

Traceback (most recent call last):
  File "/usr/lib/python3/dist-packages/urllib3/connectionpool.py", line 600, in urlopen
    chunked=chunked)
  File "/usr/lib/python3/dist-packages/urllib3/connectionpool.py", line 354, in _make_request
    conn.request(method, url, **httplib_request_kw)
  File "/usr/lib/python3.7/http/client.py", line 1244, in request
    self._send_request(method, url, body, headers, encode_chunked)
  File "/usr/lib/python3.7/http/client.py", line 1290, in _send_request
    self.endheaders(body, encode_chunked=encode_chunked)
  File "/usr/lib/python3.7/http/client.py", line 1239, in endheaders
    self._send_output(message_body, encode_chunked=encode_chunked)
  File "/usr/lib/python3.7/http/client.py", line 1026, in _send_output
    self.send(msg)
  File "/usr/lib/python3.7/http/client.py", line 966, in send
    self.connect()
  File "/usr/lib/python3/dist-packages/urllib3/connection.py", line 181, in connect
    conn = self._new_conn()
  File "/usr/lib/python3/dist-packages/urllib3/connection.py", line 168, in _new_conn
    self, "Failed to establish a new connection: %s" % e)
urllib3.exceptions.NewConnectionError: <urllib3.connection.HTTPConnection object at 0x75e5bb50>: Failed to establish a new connection: [Errno 111] Connection refused

During handling of the above exception, another exception occurred:

Traceback (most recent call last):
  File "/usr/lib/python3/dist-packages/requests/adapters.py", line 449, in send
    timeout=timeout
  File "/usr/lib/python3/dist-packages/urllib3/connectionpool.py", line 638, in urlopen
    _stacktrace=sys.exc_info()[2])
  File "/usr/lib/python3/dist-packages/urllib3/util/retry.py", line 398, in increment
    raise MaxRetryError(_pool, url, error or ResponseError(cause))
urllib3.exceptions.MaxRetryError: HTTPConnectionPool(host='localhost', port=3009): Max retries exceeded with url: /addData (Caused by NewConnectionError('<urllib3.connection.HTTPConnection object at 0x75e5bb50>: Failed to establish a new connection: [Errno 111] Connection refused'))

During handling of the above exception, another exception occurred:

Traceback (most recent call last):
  File "/home/s60030037/tempSensorRTC/temp_rtc/tempSensorRTC.py", line 26, in <module>
    res=requests.post('http://localhost:3009/addData',tempSensorRTC)
  File "/usr/lib/python3/dist-packages/requests/api.py", line 116, in post
    return request('post', url, data=data, json=json, **kwargs)
  File "/usr/lib/python3/dist-packages/requests/api.py", line 60, in request
    return session.request(method=method, url=url, **kwargs)
  File "/usr/lib/python3/dist-packages/requests/sessions.py", line 533, in request
    resp = self.send(prep, **send_kwargs)
  File "/usr/lib/python3/dist-packages/requests/sessions.py", line 646, in send
    r = adapter.send(request, **kwargs)
  File "/usr/lib/python3/dist-packages/requests/adapters.py", line 516, in send
    raise ConnectionError(e, request=request)
requests.exceptions.ConnectionError: HTTPConnectionPool(host='localhost', port=3009): Max retries exceeded with url: /addData (Caused by NewConnectionError('<urllib3.connection.HTTPConnection object at 0x75e5bb50>: Failed to establish a new connection: [Errno 111] Connection refused'))
Traceback (most recent call last):
  File "/usr/lib/python3/dist-packages/urllib3/connection.py", line 159, in _new_conn
    (self._dns_host, self.port), self.timeout, **extra_kw)
  File "/usr/lib/python3/dist-packages/urllib3/util/connection.py", line 80, in create_connection
    raise err
  File "/usr/lib/python3/dist-packages/urllib3/util/connection.py", line 70, in create_connection
    sock.connect(sa)
ConnectionRefusedError: [Errno 111] Connection refused

During handling of the above exception, another exception occurred:

Traceback (most recent call last):
  File "/usr/lib/python3/dist-packages/urllib3/connectionpool.py", line 600, in urlopen
    chunked=chunked)
  File "/usr/lib/python3/dist-packages/urllib3/connectionpool.py", line 354, in _make_request
    conn.request(method, url, **httplib_request_kw)
  File "/usr/lib/python3.7/http/client.py", line 1244, in request
    self._send_request(method, url, body, headers, encode_chunked)
  File "/usr/lib/python3.7/http/client.py", line 1290, in _send_request
    self.endheaders(body, encode_chunked=encode_chunked)
  File "/usr/lib/python3.7/http/client.py", line 1239, in endheaders
    self._send_output(message_body, encode_chunked=encode_chunked)
  File "/usr/lib/python3.7/http/client.py", line 1026, in _send_output
    self.send(msg)
  File "/usr/lib/python3.7/http/client.py", line 966, in send
    self.connect()
  File "/usr/lib/python3/dist-packages/urllib3/connection.py", line 181, in connect
    conn = self._new_conn()
  File "/usr/lib/python3/dist-packages/urllib3/connection.py", line 168, in _new_conn
    self, "Failed to establish a new connection: %s" % e)
urllib3.exceptions.NewConnectionError: <urllib3.connection.HTTPConnection object at 0x75e600d0>: Failed to establish a new connection: [Errno 111] Connection refused

During handling of the above exception, another exception occurred:

Traceback (most recent call last):
  File "/usr/lib/python3/dist-packages/requests/adapters.py", line 449, in send
    timeout=timeout
  File "/usr/lib/python3/dist-packages/urllib3/connectionpool.py", line 638, in urlopen
    _stacktrace=sys.exc_info()[2])
  File "/usr/lib/python3/dist-packages/urllib3/util/retry.py", line 398, in increment
    raise MaxRetryError(_pool, url, error or ResponseError(cause))
urllib3.exceptions.MaxRetryError: HTTPConnectionPool(host='localhost', port=3009): Max retries exceeded with url: /addData (Caused by NewConnectionError('<urllib3.connection.HTTPConnection object at 0x75e600d0>: Failed to establish a new connection: [Errno 111] Connection refused'))

During handling of the above exception, another exception occurred:

Traceback (most recent call last):
  File "/home/s60030037/tempSensorRTC/temp_rtc/tempSensorRTC.py", line 26, in <module>
    res=requests.post('http://localhost:3009/addData',tempSensorRTC)
  File "/usr/lib/python3/dist-packages/requests/api.py", line 116, in post
    return request('post', url, data=data, json=json, **kwargs)
  File "/usr/lib/python3/dist-packages/requests/api.py", line 60, in request
    return session.request(method=method, url=url, **kwargs)
  File "/usr/lib/python3/dist-packages/requests/sessions.py", line 533, in request
    resp = self.send(prep, **send_kwargs)
  File "/usr/lib/python3/dist-packages/requests/sessions.py", line 646, in send
    r = adapter.send(request, **kwargs)
  File "/usr/lib/python3/dist-packages/requests/adapters.py", line 516, in send
    raise ConnectionError(e, request=request)
requests.exceptions.ConnectionError: HTTPConnectionPool(host='localhost', port=3009): Max retries exceeded with url: /addData (Caused by NewConnectionError('<urllib3.connection.HTTPConnection object at 0x75e600d0>: Failed to establish a new connection: [Errno 111] Connection refused'))
<Response [200]>
<Response [200]>
<Response [200]>
<Response [200]>
<Response [200]>
<Response [200]>
<Response [200]>
<Response [200]>
Traceback (most recent call last):
  File "/usr/lib/python3/dist-packages/urllib3/connection.py", line 159, in _new_conn
    (self._dns_host, self.port), self.timeout, **extra_kw)
  File "/usr/lib/python3/dist-packages/urllib3/util/connection.py", line 80, in create_connection
    raise err
  File "/usr/lib/python3/dist-packages/urllib3/util/connection.py", line 70, in create_connection
    sock.connect(sa)
ConnectionRefusedError: [Errno 111] Connection refused

During handling of the above exception, another exception occurred:

Traceback (most recent call last):
  File "/usr/lib/python3/dist-packages/urllib3/connectionpool.py", line 600, in urlopen
    chunked=chunked)
  File "/usr/lib/python3/dist-packages/urllib3/connectionpool.py", line 354, in _make_request
    conn.request(method, url, **httplib_request_kw)
  File "/usr/lib/python3.7/http/client.py", line 1244, in request
    self._send_request(method, url, body, headers, encode_chunked)
  File "/usr/lib/python3.7/http/client.py", line 1290, in _send_request
    self.endheaders(body, encode_chunked=encode_chunked)
  File "/usr/lib/python3.7/http/client.py", line 1239, in endheaders
    self._send_output(message_body, encode_chunked=encode_chunked)
  File "/usr/lib/python3.7/http/client.py", line 1026, in _send_output
    self.send(msg)
  File "/usr/lib/python3.7/http/client.py", line 966, in send
    self.connect()
  File "/usr/lib/python3/dist-packages/urllib3/connection.py", line 181, in connect
    conn = self._new_conn()
  File "/usr/lib/python3/dist-packages/urllib3/connection.py", line 168, in _new_conn
    self, "Failed to establish a new connection: %s" % e)
urllib3.exceptions.NewConnectionError: <urllib3.connection.HTTPConnection object at 0x75e19e50>: Failed to establish a new connection: [Errno 111] Connection refused

During handling of the above exception, another exception occurred:

Traceback (most recent call last):
  File "/usr/lib/python3/dist-packages/requests/adapters.py", line 449, in send
    timeout=timeout
  File "/usr/lib/python3/dist-packages/urllib3/connectionpool.py", line 638, in urlopen
    _stacktrace=sys.exc_info()[2])
  File "/usr/lib/python3/dist-packages/urllib3/util/retry.py", line 398, in increment
    raise MaxRetryError(_pool, url, error or ResponseError(cause))
urllib3.exceptions.MaxRetryError: HTTPConnectionPool(host='localhost', port=3009): Max retries exceeded with url: /addData (Caused by NewConnectionError('<urllib3.connection.HTTPConnection object at 0x75e19e50>: Failed to establish a new connection: [Errno 111] Connection refused'))

During handling of the above exception, another exception occurred:

Traceback (most recent call last):
  File "/home/s60030037/tempSensorRTC/temp_rtc/tempSensorRTC.py", line 26, in <module>
    res=requests.post('http://localhost:3009/addData',tempSensorRTC)
  File "/usr/lib/python3/dist-packages/requests/api.py", line 116, in post
    return request('post', url, data=data, json=json, **kwargs)
  File "/usr/lib/python3/dist-packages/requests/api.py", line 60, in request
    return session.request(method=method, url=url, **kwargs)
  File "/usr/lib/python3/dist-packages/requests/sessions.py", line 533, in request
    resp = self.send(prep, **send_kwargs)
  File "/usr/lib/python3/dist-packages/requests/sessions.py", line 646, in send
    r = adapter.send(request, **kwargs)
  File "/usr/lib/python3/dist-packages/requests/adapters.py", line 516, in send
    raise ConnectionError(e, request=request)
requests.exceptions.ConnectionError: HTTPConnectionPool(host='localhost', port=3009): Max retries exceeded with url: /addData (Caused by NewConnectionError('<urllib3.connection.HTTPConnection object at 0x75e19e50>: Failed to establish a new connection: [Errno 111] Connection refused'))
Traceback (most recent call last):
  File "/usr/lib/python3/dist-packages/urllib3/connection.py", line 159, in _new_conn
    (self._dns_host, self.port), self.timeout, **extra_kw)
  File "/usr/lib/python3/dist-packages/urllib3/util/connection.py", line 80, in create_connection
    raise err
  File "/usr/lib/python3/dist-packages/urllib3/util/connection.py", line 70, in create_connection
    sock.connect(sa)
ConnectionRefusedError: [Errno 111] Connection refused

During handling of the above exception, another exception occurred:

Traceback (most recent call last):
  File "/usr/lib/python3/dist-packages/urllib3/connectionpool.py", line 600, in urlopen
    chunked=chunked)
  File "/usr/lib/python3/dist-packages/urllib3/connectionpool.py", line 354, in _make_request
    conn.request(method, url, **httplib_request_kw)
  File "/usr/lib/python3.7/http/client.py", line 1244, in request
    self._send_request(method, url, body, headers, encode_chunked)
  File "/usr/lib/python3.7/http/client.py", line 1290, in _send_request
    self.endheaders(body, encode_chunked=encode_chunked)
  File "/usr/lib/python3.7/http/client.py", line 1239, in endheaders
    self._send_output(message_body, encode_chunked=encode_chunked)
  File "/usr/lib/python3.7/http/client.py", line 1026, in _send_output
    self.send(msg)
  File "/usr/lib/python3.7/http/client.py", line 966, in send
    self.connect()
  File "/usr/lib/python3/dist-packages/urllib3/connection.py", line 181, in connect
    conn = self._new_conn()
  File "/usr/lib/python3/dist-packages/urllib3/connection.py", line 168, in _new_conn
    self, "Failed to establish a new connection: %s" % e)
urllib3.exceptions.NewConnectionError: <urllib3.connection.HTTPConnection object at 0x75e25ad0>: Failed to establish a new connection: [Errno 111] Connection refused

During handling of the above exception, another exception occurred:

Traceback (most recent call last):
  File "/usr/lib/python3/dist-packages/requests/adapters.py", line 449, in send
    timeout=timeout
  File "/usr/lib/python3/dist-packages/urllib3/connectionpool.py", line 638, in urlopen
    _stacktrace=sys.exc_info()[2])
  File "/usr/lib/python3/dist-packages/urllib3/util/retry.py", line 398, in increment
    raise MaxRetryError(_pool, url, error or ResponseError(cause))
urllib3.exceptions.MaxRetryError: HTTPConnectionPool(host='localhost', port=3009): Max retries exceeded with url: /addData (Caused by NewConnectionError('<urllib3.connection.HTTPConnection object at 0x75e25ad0>: Failed to establish a new connection: [Errno 111] Connection refused'))

During handling of the above exception, another exception occurred:

Traceback (most recent call last):
  File "/home/s60030037/tempSensorRTC/temp_rtc/tempSensorRTC.py", line 26, in <module>
    res=requests.post('http://localhost:3009/addData',tempSensorRTC)
  File "/usr/lib/python3/dist-packages/requests/api.py", line 116, in post
    return request('post', url, data=data, json=json, **kwargs)
  File "/usr/lib/python3/dist-packages/requests/api.py", line 60, in request
    return session.request(method=method, url=url, **kwargs)
  File "/usr/lib/python3/dist-packages/requests/sessions.py", line 533, in request
    resp = self.send(prep, **send_kwargs)
  File "/usr/lib/python3/dist-packages/requests/sessions.py", line 646, in send
    r = adapter.send(request, **kwargs)
  File "/usr/lib/python3/dist-packages/requests/adapters.py", line 516, in send
    raise ConnectionError(e, request=request)
requests.exceptions.ConnectionError: HTTPConnectionPool(host='localhost', port=3009): Max retries exceeded with url: /addData (Caused by NewConnectionError('<urllib3.connection.HTTPConnection object at 0x75e25ad0>: Failed to establish a new connection: [Errno 111] Connection refused'))
<Response [200]>
<Response [200]>
<Response [200]>
<Response [200]>
<Response [200]>
<Response [200]>
<Response [200]>
<Response [200]>
<Response [200]>
<Response [200]>
<Response [200]>
<Response [200]>
<Response [200]>
<Response [200]>
<Response [200]>
<Response [200]>
<Response [200]>
<Response [200]>
<Response [200]>
<Response [200]>
<Response [200]>
<Response [200]>
<Response [200]>
<Response [200]>
<Response [200]>
<Response [200]>
<Response [200]>
<Response [200]>
<Response [200]>
<Response [200]>
<Response [200]>
<Response [200]>
<Response [200]>
<Response [200]>
<Response [200]>
<Response [200]>
<Response [200]>
<Response [200]>
<Response [200]>
<Response [200]>
<Response [200]>
<Response [200]>
<Response [200]>
<Response [200]>
<Response [200]>
<Response [200]>
<Response [200]>
<Response [200]>
<Response [200]>
<Response [200]>
<Response [200]>
<Response [200]>
<Response [200]>
<Response [200]>
<Response [200]>
<Response [200]>
<Response [200]>
<Response [200]>
<Response [200]>
<Response [200]>
<Response [200]>
<Response [200]>
<Response [200]>
<Response [200]>
<Response [200]>
<Response [200]>
<Response [200]>
<Response [200]>
<Response [200]>
<Response [200]>
<Response [200]>
<Response [200]>
<Response [200]>
<Response [200]>
<Response [200]>
<Response [200]>
<Response [200]>
<Response [200]>
<Response [200]>
<Response [200]>
<Response [200]>
<Response [200]>
<Response [200]>
<Response [200]>
<Response [200]>
<Response [200]>
<Response [200]>
<Response [200]>
<Response [200]>
<Response [200]>
<Response [200]>
<Response [200]>
<Response [200]>
